<?xml version="1.0" ?>
<!-- =================================================================================== -->
<!-- |    This document was autogenerated by xacro from src/robot_description/urdf/robot.urdf.xacro | -->
<!-- |    EDITING THIS FILE BY HAND IS NOT RECOMMENDED                                 | -->
<!-- =================================================================================== -->
<robot name="mobile_robot">
  <!-- Robot base -->
  <link name="base_link">
    <visual>
      <geometry>
        <box size="0.5 0.3 0.2"/>
      </geometry>
      <material name="base_color">
        <color rgba="0.6 0.6 0.6 1.0"/>
      </material>
    </visual>
  </link>
  <!-- Stereo camera -->
  <link name="stereo_camera">
    <visual>
      <geometry>
        <box size="0.1 0.1 0.05"/>
      </geometry>
      <material name="camera_color">
        <color rgba="0.2 0.2 0.2 1.0"/>
      </material>
    </visual>
  </link>
  <!-- Joint connecting camera to base -->
  <joint name="camera_joint" type="fixed">
    <parent link="base_link"/>
    <child link="stereo_camera"/>
    <origin xyz="0.0 0.0 0.2"/>
    <!-- Adjust position as necessary -->
  </joint>
  <!-- Left and Right Wheels -->
  <link name="left_wheel"/>
  <link name="right_wheel"/>
  <joint name="left_wheel_joint" type="continuous">
    <parent link="base_link"/>
    <child link="left_wheel"/>
    <origin xyz="-0.1 0.15 0.0"/>
    <axis xyz="0 1 0"/>
  </joint>
  <joint name="right_wheel_joint" type="continuous">
    <parent link="base_link"/>
    <child link="right_wheel"/>
    <origin xyz="-0.1 -0.15 0.0"/>
    <axis xyz="0 1 0"/>
  </joint>
  <!-- Differential drive plugin -->
  <gazebo>
    <plugin filename="libgazebo_ros_diff_drive.so" name="diff_drive_controller">
      <ros>
        <namespace>/</namespace>
        <remapping>cmd_vel:=/cmd_vel</remapping>
        <remapping>odom:=/odom</remapping>
      </ros>
      <left_joint>left_wheel_joint</left_joint>
      <right_joint>right_wheel_joint</right_joint>
      <wheel_separation>0.3</wheel_separation>
      <wheel_diameter>0.15</wheel_diameter>
    </plugin>
  </gazebo>
  <!-- Left and right stereo cameras -->
  <gazebo reference="stereo_camera">
    <sensor name="left_camera" type="camera">
      <camera name="left_camera">
        <horizontal_fov>1.047</horizontal_fov>
        <image>
          <width>640</width>
          <height>480</height>
          <format>R8G8B8</format>
        </image>
        <clip>
          <near>0.1</near>
          <far>100</far>
        </clip>
      </camera>
      <plugin filename="libgazebo_ros_camera.so" name="camera_controller">
        <always_on>true</always_on>
        <update_rate>30.0</update_rate>
        <camera_name>left_camera</camera_name>
        <image_topic_name>/stereo_camera/left/image_raw</image_topic_name>
      </plugin>
    </sensor>
    <sensor name="right_camera" type="camera">
      <camera name="right_camera">
        <horizontal_fov>1.047</horizontal_fov>
        <image>
          <width>640</width>
          <height>480</height>
          <format>R8G8B8</format>
        </image>
        <clip>
          <near>0.1</near>
          <far>100</far>
        </clip>
      </camera>
      <plugin filename="libgazebo_ros_camera.so" name="camera_controller">
        <always_on>true</always_on>
        <update_rate>30.0</update_rate>
        <camera_name>right_camera</camera_name>
        <image_topic_name>/stereo_camera/right/image_raw</image_topic_name>
      </plugin>
    </sensor>
  </gazebo>
</robot>
